Workbook

Sheet Sheet1
A1: Date :06.11.2025 | K1: Time :
A2: Row Labels | B2: SR EXECUTIVE Names | C2: Executive | E2: Existing Team | F2: Due List Total | G2: RCVD | H2: BLC | I2: % | K2: Target 8% | L2: RCVD | M2: BLC | N2: % | P2: 7th July % | R2: 5th % | S2: 4th % | T2: 3rd % | U2: 1st % | W2: 2W | X2: RCVD | Y2: BLC | Z2: % | AB2: 3W | AC2: RCVD | AD2: BLC | AE2: %
A3: Sai Rekha | C3: =C4+C10+C14+C19+C24+C28+C12 -> 31 | F3: =F4+F10+F14+F19+F24+F28+F12 -> 3242 | G3: =G4+G10+G14+G19+G24+G28+G12 -> 403 | H3: =H4+H10+H14+H19+H24+H28+H12 -> 2839 | I3: =G3/F3 -> 0.12430598 | K3: =K4+K10+K14+K19+K24+K28+K12 -> 389.04 | L3: =L4+L10+L14+L19+L24+L28+L12 -> 0 | M3: =M4+M10+M14+M19+M24+M28+M12 -> 389.04 | N3: =L3/F3 -> 0 | P3: 0.154 | R3: 0.078038248 | S3: 0.025601481 | T3: 0.016964837 | U3: 0.0037014189 | W3: =W4+W10+W14+W19+W24+W28+W12 -> 1757 | X3: =X4+X10+X14+X19+X24+X28+X12 -> 147 | Y3: =Y4+Y10+Y14+Y19+Y24+Y28+Y12 -> 1610 | Z3: =X3/W3 -> 0.083665339 | AB3: =AB4+AB10+AB14+AB19+AB24+AB28+AB12 -> 1485 | AC3: =AC4+AC10+AC14+AC19+AC24+AC28+AC12 -> 256 | AD3: =AD4+AD10+AD14+AD19+AD24+AD28+AD12 -> 1229 | AE3: =AC3/AB3 -> 0.17239057
A4: Jamanna | C4: =SUM(C5:C9) -> 7 | F4: =SUM(F5:F9) -> 562 | G4: =SUM(G5:G9) -> 61 | H4: =SUM(H5:H9) -> 501 | I4: =G4/F4 -> 0.10854093 | K4: =SUM(K5:K9) -> 67.44 | L4: =SUM(L5:L9) -> 0 | M4: =SUM(M5:M9) -> 67.44 | N4: =L4/F4 -> 0 | P4: 0.16736402 | R4: 0.067615658 | S4: 0.026690391 | T4: 0.012455516 | U4: 0.0017793594 | W4: =SUM(W5:W9) -> 449 | X4: =SUM(X5:X9) -> 36 | Y4: =SUM(Y5:Y9) -> 413 | Z4: =X4/W4 -> 0.080178174 | AB4: =SUM(AB5:AB9) -> 113 | AC4: =SUM(AC5:AC9) -> 25 | AD4: =SUM(AD5:AD9) -> 88 | AE4: =AC4/AB4 -> 0.22123894
A5: Alampur | C5: 1 | F5: =VLOOKUP(A:A,[1]Sheet1!$A:$D,4,0) -> 71 | G5: =VLOOKUP(A:A,[1]Sheet1!$A:$C,3,0) -> 10 | H5: =F5-G5 -> 61 | I5: =G5/F5 -> 0.14084507 | K5: =F5*12/100 -> 8.52 | M5: =K5-L5 -> 8.52 | N5: =L5/F5 -> 0 | P5: 0.2 | R5: 0.12676056 | S5: 0 | T5: 0.014084507 | U5: 0 | W5: =VLOOKUP(A:A,'[1]2w & 3w'!$A:$D,4,0) -> 59 | X5: =VLOOKUP(A:A,'[1]2w & 3w'!$A:$C,3,0) -> 7 | Y5: =W5-X5 -> 52 | Z5: =X5/W5 -> 0.11864407 | AB5: =VLOOKUP(A:A,'[1]2w & 3w'!$A:$G,7,0) -> 12 | AC5: =VLOOKUP(A:A,'[1]2w & 3w'!$A:$F,6,0) -> 3 | AD5: =AB5-AC5 -> 9 | AE5: =AC5/AB5 -> 0.25
A6: Gadwal | C6: 2 | F6: =VLOOKUP(A:A,[1]Sheet1!$A:$D,4,0) -> 160 | G6: =VLOOKUP(A:A,[1]Sheet1!$A:$C,3,0) -> 24 | H6: =F6-G6 -> 136 | I6: =G6/F6 -> 0.15 | K6: =F6*12/100 -> 19.2 | M6: =K6-L6 -> 19.2 | N6: =L6/F6 -> 0 | P6: 0.19897959 | R6: 0.0875 | S6: 0.0375 | T6: 0.01875 | U6: 0.00625 | W6: =VLOOKUP(A:A,'[1]2w & 3w'!$A:$D,4,0) -> 79 | X6: =VLOOKUP(A:A,'[1]2w & 3w'!$A:$C,3,0) -> 6 | Y6: =W6-X6 -> 73 | Z6: =X6/W6 -> 0.075949367 | AB6: =VLOOKUP(A:A,'[1]2w & 3w'!$A:$G,7,0) -> 81 | AC6: =VLOOKUP(A:A,'[1]2w & 3w'!$A:$F,6,0) -> 18 | AD6: =AB6-AC6 -> 63 | AE6: =AC6/AB6 -> 0.22222222
A7: Ieeza | C7: 2 | F7: =VLOOKUP(A:A,[1]Sheet1!$A:$D,4,0) -> 174 | G7: =VLOOKUP(A:A,[1]Sheet1!$A:$C,3,0) -> 13 | H7: =F7-G7 -> 161 | I7: =G7/F7 -> 0.074712644 | K7: =F7*12/100 -> 20.88 | M7: =K7-L7 -> 20.88 | N7: =L7/F7 -> 0 | P7: 0.16444444 | R7: 0.028735632 | S7: 0.040229885 | T7: 0.0057471264 | U7: 0 | W7: =VLOOKUP(A:A,'[1]2w & 3w'!$A:$D,4,0) -> 166 | X7: =VLOOKUP(A:A,'[1]2w & 3w'!$A:$C,3,0) -> 11 | Y7: =W7-X7 -> 155 | Z7: =X7/W7 -> 0.06626506 | AB7: =VLOOKUP(A:A,'[1]2w & 3w'!$A:$G,7,0) -> 8 | AC7: =VLOOKUP(A:A,'[1]2w & 3w'!$A:$F,6,0) -> 2 | AD7: =AB7-AC7 -> 6 | AE7: =AC7/AB7 -> 0.25
A8: Shanthinagar | C8: 1 | F8: =VLOOKUP(A:A,[1]Sheet1!$A:$D,4,0) -> 102 | G8: =VLOOKUP(A:A,[1]Sheet1!$A:$C,3,0) -> 9 | H8: =F8-G8 -> 93 | I8: =G8/F8 -> 0.088235294 | K8: =F8*12/100 -> 12.24 | M8: =K8-L8 -> 12.24 | N8: =L8/F8 -> 0 | P8: 0.1294964 | R8: 0.078431373 | S8: 0 | T8: 0.0098039216 | U8: 0 | W8: =VLOOKUP(A:A,'[1]2w & 3w'!$A:$D,4,0) -> 101 | X8: =VLOOKUP(A:A,'[1]2w & 3w'!$A:$C,3,0) -> 9 | Y8: =W8-X8 -> 92 | Z8: =X8/W8 -> 0.089108911 | AB8: =VLOOKUP(A:A,'[1]2w & 3w'!$A:$G,7,0) -> 1 | AC8: =VLOOKUP(A:A,'[1]2w & 3w'!$A:$F,6,0) -> 0 | AD8: =AB8-AC8 -> 1 | AE8: =AC8/AB8 -> 0
A9: Yerravalli | C9: 1 | F9: =VLOOKUP(A:A,[1]Sheet1!$A:$D,4,0) -> 55 | G9: =VLOOKUP(A:A,[1]Sheet1!$A:$C,3,0) -> 5 | H9: =F9-G9 -> 50 | I9: =G9/F9 -> 0.090909091 | K9: =F9*12/100 -> 6.6 | M9: =K9-L9 -> 6.6 | N9: =L9/F9 -> 0 | P9: 0.12987013 | R9: 0.036363636 | S9: 0.036363636 | T9: 0.018181818 | U9: 0 | W9: =VLOOKUP(A:A,'[1]2w & 3w'!$A:$D,4,0) -> 44 | X9: =VLOOKUP(A:A,'[1]2w & 3w'!$A:$C,3,0) -> 3 | Y9: =W9-X9 -> 41 | Z9: =X9/W9 -> 0.068181818 | AB9: =VLOOKUP(A:A,'[1]2w & 3w'!$A:$G,7,0) -> 11 | AC9: =VLOOKUP(A:A,'[1]2w & 3w'!$A:$F,6,0) -> 2 | AD9: =AB9-AC9 -> 9 | AE9: =AC9/AB9 -> 0.18181818
A10: NO_ TL bhainsa | C10: =C11 -> 2 | F10: =F11 -> 235 | G10: =G11 -> 35 | H10: =H11 -> 200 | I10: =G10/F10 -> 0.14893617 | K10: =K11 -> 28.2 | L10: =L11 -> 0 | M10: =M11 -> 28.2 | N10: =L10/F10 -> 0 | P10: 0.13253012 | R10: 0.059574468 | S10: 0.042553191 | T10: 0.038297872 | U10: 0.0085106383 | W10: =W11 -> 226 | X10: =X11 -> 32 | Y10: =Y11 -> 194 | Z10: =X10/W10 -> 0.14159292 | AB10: =AB11 -> 9 | AC10: =AC11 -> 3 | AD10: =AD11 -> 6 | AE10: =AC10/AB10 -> 0.33333333
A11: Bhainsa | C11: 2 | F11: =VLOOKUP(A:A,[1]Sheet1!$A:$D,4,0) -> 235 | G11: =VLOOKUP(A:A,[1]Sheet1!$A:$C,3,0) -> 35 | H11: =F11-G11 -> 200 | I11: =G11/F11 -> 0.14893617 | K11: =F11*12/100 -> 28.2 | M11: =K11-L11 -> 28.2 | N11: =L11/F11 -> 0 | P11: 0.13253012 | R11: 0.059574468 | S11: 0.042553191 | T11: 0.038297872 | U11: 0.0085106383 | W11: =VLOOKUP(A:A,'[1]2w & 3w'!$A:$D,4,0) -> 226 | X11: =VLOOKUP(A:A,'[1]2w & 3w'!$A:$C,3,0) -> 32 | Y11: =W11-X11 -> 194 | Z11: =X11/W11 -> 0.14159292 | AB11: =VLOOKUP(A:A,'[1]2w & 3w'!$A:$G,7,0) -> 9 | AC11: =VLOOKUP(A:A,'[1]2w & 3w'!$A:$F,6,0) -> 3 | AD11: =AB11-AC11 -> 6 | AE11: =AC11/AB11 -> 0.33333333
A12: NO TL ADILABAD | C12: =C13 -> 1 | F12: =F13 -> 122 | G12: =G13 -> 10 | H12: =H13 -> 112 | I12: =G12/F12 -> 0.081967213 | K12: =K13 -> 14.64 | L12: =L13 -> 0 | M12: =M13 -> 14.64 | N12: =L12/F12 -> 0 | P12: 0.088435374 | R12: 0.049180328 | S12: 0.024590164 | T12: 0.0081967213 | U12: 0 | W12: =W13 -> 107 | X12: =X13 -> 7 | Y12: =Y13 -> 100 | Z12: =X12/W12 -> 0.065420561 | AB12: =AB13 -> 15 | AC12: =AC13 -> 3 | AD12: =AD13 -> 12 | AE12: =AC12/AB12 -> 0.2
A13: Adilabad | B13: SE ex | C13: 1 | F13: =VLOOKUP(A:A,[1]Sheet1!$A:$D,4,0) -> 122 | G13: =VLOOKUP(A:A,[1]Sheet1!$A:$C,3,0) -> 10 | H13: =F13-G13 -> 112 | I13: =G13/F13 -> 0.081967213 | K13: =F13*12/100 -> 14.64 | M13: =K13-L13 -> 14.64 | N13: =L13/F13 -> 0 | P13: 0.088435374 | R13: 0.049180328 | S13: 0.024590164 | T13: 0.0081967213 | U13: 0 | W13: =VLOOKUP(A:A,'[1]2w & 3w'!$A:$D,4,0) -> 107 | X13: =VLOOKUP(A:A,'[1]2w & 3w'!$A:$C,3,0) -> 7 | Y13: =W13-X13 -> 100 | Z13: =X13/W13 -> 0.065420561 | AB13: =VLOOKUP(A:A,'[1]2w & 3w'!$A:$G,7,0) -> 15 | AC13: =VLOOKUP(A:A,'[1]2w & 3w'!$A:$F,6,0) -> 3 | AD13: =AB13-AC13 -> 12 | AE13: =AC13/AB13 -> 0.2
A14: Vijay - MBNR | C14: =SUM(C15:C18) -> 7 | F14: =SUM(F15:F18) -> 821 | G14: =SUM(G15:G18) -> 148 | H14: =SUM(H15:H18) -> 673 | I14: =G14/F14 -> 0.18026797 | K14: =SUM(K15:K18) -> 98.52 | L14: =SUM(L15:L18) -> 0 | M14: =SUM(M15:M18) -> 98.52 | N14: =L14/F14 -> 0 | P14: 0.20671141 | R14: 0.12789281 | S14: 0.032886724 | T14: 0.015834348 | U14: 0.0036540804 | W14: =SUM(W15:W18) -> 149 | X14: =SUM(X15:X18) -> 15 | Y14: =SUM(Y15:Y18) -> 134 | Z14: =X14/W14 -> 0.10067114 | AB14: =SUM(AB15:AB18) -> 672 | AC14: =SUM(AC15:AC18) -> 133 | AD14: =SUM(AD15:AD18) -> 539 | AE14: =AC14/AB14 -> 0.19791667
A15: Kalwakurthi | C15: 1 | F15: =VLOOKUP(A:A,[1]Sheet1!$A:$D,4,0) -> 106 | G15: =VLOOKUP(A:A,[1]Sheet1!$A:$C,3,0) -> 14 | H15: =F15-G15 -> 92 | I15: =G15/F15 -> 0.13207547 | K15: =F15*12/100 -> 12.72 | M15: =K15-L15 -> 12.72 | N15: =L15/F15 -> 0 | P15: 0.1440678 | R15: 0.075471698 | S15: 0.028301887 | T15: 0.028301887 | U15: 0 | W15: =VLOOKUP(A:A,'[1]2w & 3w'!$A:$D,4,0) -> 68 | X15: =VLOOKUP(A:A,'[1]2w & 3w'!$A:$C,3,0) -> 10 | Y15: =W15-X15 -> 58 | Z15: =X15/W15 -> 0.14705882 | AB15: =VLOOKUP(A:A,'[1]2w & 3w'!$A:$G,7,0) -> 38 | AC15: =VLOOKUP(A:A,'[1]2w & 3w'!$A:$F,6,0) -> 4 | AD15: =AB15-AC15 -> 34 | AE15: =AC15/AB15 -> 0.10526316
A16: MahaboobNagar (Auto) | B16: SE ex | C16: 3 | F16: =VLOOKUP(A:A,[1]Sheet1!$A:$D,4,0) -> 330 | G16: =VLOOKUP(A:A,[1]Sheet1!$A:$C,3,0) -> 50 | H16: =F16-G16 -> 280 | I16: =G16/F16 -> 0.15151515 | K16: =F16*12/100 -> 39.6 | M16: =K16-L16 -> 39.6 | N16: =L16/F16 -> 0 | P16: 0.22175732 | R16: 0.11212121 | S16: 0.024242424 | T16: 0.012121212 | U16: 0.003030303 | W16: =VLOOKUP(A:A,'[1]2w & 3w'!$A:$D,4,0) -> 10 | X16: =VLOOKUP(A:A,'[1]2w & 3w'!$A:$C,3,0) -> 0 | Y16: =W16-X16 -> 10 | Z16: =X16/W16 -> 0 | AB16: =VLOOKUP(A:A,'[1]2w & 3w'!$A:$G,7,0) -> 320 | AC16: =VLOOKUP(A:A,'[1]2w & 3w'!$A:$F,6,0) -> 50 | AD16: =AB16-AC16 -> 270 | AE16: =AC16/AB16 -> 0.15625
A17: Nagarkurnool (2W) | C17: 1 | F17: =VLOOKUP(A:A,[1]Sheet1!$A:$D,4,0) -> 134 | G17: =VLOOKUP(A:A,[1]Sheet1!$A:$C,3,0) -> 23 | H17: =F17-G17 -> 111 | I17: =G17/F17 -> 0.17164179 | K17: =F17*12/100 -> 16.08 | M17: =K17-L17 -> 16.08 | N17: =L17/F17 -> 0 | P17: 0.2231405 | R17: 0.11940299 | S17: 0.037313433 | T17: 0.014925373 | U17: 0 | W17: =VLOOKUP(A:A,'[1]2w & 3w'!$A:$D,4,0) -> 32 | X17: =VLOOKUP(A:A,'[1]2w & 3w'!$A:$C,3,0) -> 2 | Y17: =W17-X17 -> 30 | Z17: =X17/W17 -> 0.0625 | AB17: =VLOOKUP(A:A,'[1]2w & 3w'!$A:$G,7,0) -> 102 | AC17: =VLOOKUP(A:A,'[1]2w & 3w'!$A:$F,6,0) -> 21 | AD17: =AB17-AC17 -> 81 | AE17: =AC17/AB17 -> 0.20588235
A18: Narayanpet | B18: SE ex | C18: 2 | F18: =VLOOKUP(A:A,[1]Sheet1!$A:$D,4,0) -> 251 | G18: =VLOOKUP(A:A,[1]Sheet1!$A:$C,3,0) -> 61 | H18: =F18-G18 -> 190 | I18: =G18/F18 -> 0.24302789 | K18: =F18*12/100 -> 30.12 | M18: =K18-L18 -> 30.12 | N18: =L18/F18 -> 0 | P18: 0.21348315 | R18: 0.1752988 | S18: 0.043824701 | T18: 0.015936255 | U18: 0.0079681275 | W18: =VLOOKUP(A:A,'[1]2w & 3w'!$A:$D,4,0) -> 39 | X18: =VLOOKUP(A:A,'[1]2w & 3w'!$A:$C,3,0) -> 3 | Y18: =W18-X18 -> 36 | Z18: =X18/W18 -> 0.076923077 | AB18: =VLOOKUP(A:A,'[1]2w & 3w'!$A:$G,7,0) -> 212 | AC18: =VLOOKUP(A:A,'[1]2w & 3w'!$A:$F,6,0) -> 58 | AD18: =AB18-AC18 -> 154 | AE18: =AC18/AB18 -> 0.27358491
A19: Amjed Ali | C19: =SUM(C20:C22) -> 4 | F19: =SUM(F20:F23) -> 507 | G19: =SUM(G20:G23) -> 51 | H19: =SUM(H20:H23) -> 456 | I19: =G19/F19 -> 0.10059172 | K19: =SUM(K20:K23) -> 60.84 | L19: =SUM(L20:L23) -> 0 | M19: =SUM(M20:M23) -> 60.84 | N19: =L19/F19 -> 0 | P19: 0.13868613 | R19: 0.069033531 | S19: 0.013806706 | T19: 0.013806706 | U19: 0.0039447732 | W19: =SUM(W20:W23) -> 480 | X19: =SUM(X20:X23) -> 46 | Y19: =SUM(Y20:Y23) -> 434 | Z19: =X19/W19 -> 0.095833333 | AB19: =SUM(AB20:AB23) -> 27 | AC19: =SUM(AC20:AC23) -> 5 | AD19: =SUM(AD20:AD23) -> 22 | AE19: =AC19/AB19 -> 0.18518519
A20: Devarakonda(2W) | C20: 1 | F20: =VLOOKUP(A:A,[1]Sheet1!$A:$D,4,0) -> 127 | G20: =VLOOKUP(A:A,[1]Sheet1!$A:$C,3,0) -> 17 | H20: =F20-G20 -> 110 | I20: =G20/F20 -> 0.13385827 | K20: =F20*12/100 -> 15.24 | M20: =K20-L20 -> 15.24 | N20: =L20/F20 -> 0 | P20: 0.125 | R20: 0.094488189 | S20: 0.0078740157 | T20: 0.023622047 | U20: 0.0078740157 | W20: =VLOOKUP(A:A,'[1]2w & 3w'!$A:$D,4,0) -> 120 | X20: =VLOOKUP(A:A,'[1]2w & 3w'!$A:$C,3,0) -> 17 | Y20: =W20-X20 -> 103 | Z20: =X20/W20 -> 0.14166667 | AB20: =VLOOKUP(A:A,'[1]2w & 3w'!$A:$G,7,0) -> 7 | AC20: =VLOOKUP(A:A,'[1]2w & 3w'!$A:$F,6,0) -> 0 | AD20: =AB20-AC20 -> 7 | AE20: =AC20/AB20 -> 0
A21: Miryalaguda | C21: 1 | F21: =VLOOKUP(A:A,[1]Sheet1!$A:$D,4,0) -> 113 | G21: =VLOOKUP(A:A,[1]Sheet1!$A:$C,3,0) -> 11 | H21: =F21-G21 -> 102 | I21: =G21/F21 -> 0.097345133 | K21: =F21*12/100 -> 13.56 | M21: =K21-L21 -> 13.56 | N21: =L21/F21 -> 0 | P21: 0.15789474 | R21: 0.079646018 | S21: 0.0088495575 | T21: 0.0088495575 | U21: 0 | W21: =VLOOKUP(A:A,'[1]2w & 3w'!$A:$D,4,0) -> 93 | X21: =VLOOKUP(A:A,'[1]2w & 3w'!$A:$C,3,0) -> 6 | Y21: =W21-X21 -> 87 | Z21: =X21/W21 -> 0.064516129 | AB21: =VLOOKUP(A:A,'[1]2w & 3w'!$A:$G,7,0) -> 20 | AC21: =VLOOKUP(A:A,'[1]2w & 3w'!$A:$F,6,0) -> 5 | AD21: =AB21-AC21 -> 15 | AE21: =AC21/AB21 -> 0.25
A22: Amangal | C22: 2 | F22: =VLOOKUP(A:A,[1]Sheet1!$A:$D,4,0) -> 247 | G22: =VLOOKUP(A:A,[1]Sheet1!$A:$C,3,0) -> 22 | H22: =F22-G22 -> 225 | I22: =G22/F22 -> 0.089068826 | K22: =F22*12/100 -> 29.64 | M22: =K22-L22 -> 29.64 | N22: =L22/F22 -> 0 | P22: 0.098360656 | R22: 0.056680162 | S22: 0.020242915 | T22: 0.012145749 | U22: 0 | W22: =VLOOKUP(A:A,'[1]2w & 3w'!$A:$D,4,0) -> 247 | X22: =VLOOKUP(A:A,'[1]2w & 3w'!$A:$C,3,0) -> 22 | Y22: =W22-X22 -> 225 | Z22: =X22/W22 -> 0.089068826 | AB22: =VLOOKUP(A:A,'[1]2w & 3w'!$A:$G,7,0) -> 0 | AC22: =VLOOKUP(A:A,'[1]2w & 3w'!$A:$F,6,0) -> 0 | AD22: =AB22-AC22 -> 0 | AE22: 0
A23: Tukkuguda | F23: =VLOOKUP(A:A,[1]Sheet1!$A:$D,4,0) -> 20 | G23: =VLOOKUP(A:A,[1]Sheet1!$A:$C,3,0) -> 1 | H23: =F23-G23 -> 19 | I23: =G23/F23 -> 0.05 | K23: =F23*12/100 -> 2.4 | M23: =K23-L23 -> 2.4 | N23: =L23/F23 -> 0 | P23: 0 | R23: 0 | S23: 0 | T23: 0 | U23: 0.05 | W23: =VLOOKUP(A:A,'[1]2w & 3w'!$A:$D,4,0) -> 20 | X23: =VLOOKUP(A:A,'[1]2w & 3w'!$A:$C,3,0) -> 1 | Y23: =W23-X23 -> 19 | Z23: =X23/W23 -> 0.05 | AB23: =VLOOKUP(A:A,'[1]2w & 3w'!$A:$G,7,0) -> 0 | AC23: =VLOOKUP(A:A,'[1]2w & 3w'!$A:$F,6,0) -> 0 | AD23: =AB23-AC23 -> 0 | AE23: 0
A24: Satish | C24: =SUM(C25:C27) -> 5 | F24: =SUM(F25:F27) -> 488 | G24: =SUM(G25:G27) -> 57 | H24: =SUM(H25:H27) -> 431 | I24: =G24/F24 -> 0.11680328 | K24: =SUM(K25:K27) -> 58.56 | L24: =SUM(L25:L27) -> 0 | M24: =SUM(M25:M27) -> 58.56 | N24: =L24/F24 -> 0 | P24: 0.15441176 | R24: 0.069672131 | S24: 0.026639344 | T24: 0.016393443 | U24: 0.0040983607 | W24: =SUM(W25:W27) -> 135 | X24: =SUM(X25:X27) -> 5 | Y24: =SUM(Y25:Y27) -> 130 | Z24: =X24/W24 -> 0.037037037 | AB24: =SUM(AB25:AB27) -> 353 | AC24: =SUM(AC25:AC27) -> 52 | AD24: =SUM(AD25:AD27) -> 301 | AE24: =AC24/AB24 -> 0.14730878
A25: Bhongir | B25: SE ex | C25: 3 | F25: =VLOOKUP(A:A,[1]Sheet1!$A:$D,4,0) -> 271 | G25: =VLOOKUP(A:A,[1]Sheet1!$A:$C,3,0) -> 38 | H25: =F25-G25 -> 233 | I25: =G25/F25 -> 0.1402214 | K25: =F25*12/100 -> 32.52 | M25: =K25-L25 -> 32.52 | N25: =L25/F25 -> 0 | P25: 0.16544118 | R25: 0.073800738 | S25: 0.040590406 | T25: 0.022140221 | U25: 0.0036900369 | W25: =VLOOKUP(A:A,'[1]2w & 3w'!$A:$D,4,0) -> 18 | X25: =VLOOKUP(A:A,'[1]2w & 3w'!$A:$C,3,0) -> 0 | Y25: =W25-X25 -> 18 | Z25: =X25/W25 -> 0 | AB25: =VLOOKUP(A:A,'[1]2w & 3w'!$A:$G,7,0) -> 253 | AC25: =VLOOKUP(A:A,'[1]2w & 3w'!$A:$F,6,0) -> 38 | AD25: =AB25-AC25 -> 215 | AE25: =AC25/AB25 -> 0.15019763
A26: Nalgonda | B26: SE ex | C26: 1 | F26: =VLOOKUP(A:A,[1]Sheet1!$A:$D,4,0) -> 121 | G26: =VLOOKUP(A:A,[1]Sheet1!$A:$C,3,0) -> 12 | H26: =F26-G26 -> 109 | I26: =G26/F26 -> 0.099173554 | K26: =F26*12/100 -> 14.52 | M26: =K26-L26 -> 14.52 | N26: =L26/F26 -> 0 | P26: 0.15 | R26: 0.066115702 | S26: 0.016528926 | T26: 0.0082644628 | U26: 0.0082644628 | W26: =VLOOKUP(A:A,'[1]2w & 3w'!$A:$D,4,0) -> 41 | X26: =VLOOKUP(A:A,'[1]2w & 3w'!$A:$C,3,0) -> 1 | Y26: =W26-X26 -> 40 | Z26: =X26/W26 -> 0.024390244 | AB26: =VLOOKUP(A:A,'[1]2w & 3w'!$A:$G,7,0) -> 80 | AC26: =VLOOKUP(A:A,'[1]2w & 3w'!$A:$F,6,0) -> 11 | AD26: =AB26-AC26 -> 69 | AE26: =AC26/AB26 -> 0.1375
A27: Huzurnagar | B27: SE ex | C27: 1 | F27: =VLOOKUP(A:A,[1]Sheet1!$A:$D,4,0) -> 96 | G27: =VLOOKUP(A:A,[1]Sheet1!$A:$C,3,0) -> 7 | H27: =F27-G27 -> 89 | I27: =G27/F27 -> 0.072916667 | K27: =F27*12/100 -> 11.52 | M27: =K27-L27 -> 11.52 | N27: =L27/F27 -> 0 | P27: 0.12903226 | R27: 0.0625 | S27: 0 | T27: 0.010416667 | U27: 0 | W27: =VLOOKUP(A:A,'[1]2w & 3w'!$A:$D,4,0) -> 76 | X27: =VLOOKUP(A:A,'[1]2w & 3w'!$A:$C,3,0) -> 4 | Y27: =W27-X27 -> 72 | Z27: =X27/W27 -> 0.052631579 | AB27: =VLOOKUP(A:A,'[1]2w & 3w'!$A:$G,7,0) -> 20 | AC27: =VLOOKUP(A:A,'[1]2w & 3w'!$A:$F,6,0) -> 3 | AD27: =AB27-AC27 -> 17 | AE27: =AC27/AB27 -> 0.15
A28: Shamshuddin | C28: =SUM(C29:C33) -> 5 | F28: =SUM(F29:F33) -> 507 | G28: =SUM(G29:G33) -> 41 | H28: =SUM(H29:H33) -> 466 | I28: =G28/F28 -> 0.08086785 | K28: =SUM(K29:K33) -> 60.84 | L28: =SUM(L29:L33) -> 0 | M28: =SUM(M29:M33) -> 60.84 | N28: =L28/F28 -> 0 | P28: 0.13229572 | R28: 0.041420118 | S28: 0.015779093 | T28: 0.019723866 | U28: 0.0039447732 | W28: =SUM(W29:W33) -> 211 | X28: =SUM(X29:X33) -> 6 | Y28: =SUM(Y29:Y33) -> 205 | Z28: =X28/W28 -> 0.028436019 | AB28: =SUM(AB29:AB33) -> 296 | AC28: =SUM(AC29:AC33) -> 35 | AD28: =SUM(AD29:AD33) -> 261 | AE28: =AC28/AB28 -> 0.11824324
A29: Huzurabad | C29: 1 | F29: =VLOOKUP(A:A,[1]Sheet1!$A:$D,4,0) -> 76 | G29: =VLOOKUP(A:A,[1]Sheet1!$A:$C,3,0) -> 5 | H29: =F29-G29 -> 71 | I29: =G29/F29 -> 0.065789474 | K29: =F29*12/100 -> 9.12 | M29: =K29-L29 -> 9.12 | N29: =L29/F29 -> 0 | P29: 0.097560976 | R29: 0.039473684 | S29: 0.013157895 | T29: 0.013157895 | U29: 0 | W29: =VLOOKUP(A:A,'[1]2w & 3w'!$A:$D,4,0) -> 45 | X29: =VLOOKUP(A:A,'[1]2w & 3w'!$A:$C,3,0) -> 2 | Y29: =W29-X29 -> 43 | Z29: =X29/W29 -> 0.044444444 | AB29: =VLOOKUP(A:A,'[1]2w & 3w'!$A:$G,7,0) -> 31 | AC29: =VLOOKUP(A:A,'[1]2w & 3w'!$A:$F,6,0) -> 3 | AD29: =AB29-AC29 -> 28 | AE29: =AC29/AB29 -> 0.096774194
A30: Peddapally | C30: 1 | F30: =VLOOKUP(A:A,[1]Sheet1!$A:$D,4,0) -> 93 | G30: =VLOOKUP(A:A,[1]Sheet1!$A:$C,3,0) -> 2 | H30: =F30-G30 -> 91 | I30: =G30/F30 -> 0.021505376 | K30: =F30*12/100 -> 11.16 | M30: =K30-L30 -> 11.16 | N30: =L30/F30 -> 0 | P30: 0.14754098 | R30: 0.021505376 | S30: 0 | T30: 0 | U30: 0 | W30: =VLOOKUP(A:A,'[1]2w & 3w'!$A:$D,4,0) -> 62 | X30: =VLOOKUP(A:A,'[1]2w & 3w'!$A:$C,3,0) -> 0 | Y30: =W30-X30 -> 62 | Z30: =X30/W30 -> 0 | AB30: =VLOOKUP(A:A,'[1]2w & 3w'!$A:$G,7,0) -> 31 | AC30: =VLOOKUP(A:A,'[1]2w & 3w'!$A:$F,6,0) -> 2 | AD30: =AB30-AC30 -> 29 | AE30: =AC30/AB30 -> 0.064516129
A31: Mancherial | F31: =VLOOKUP(A:A,[1]Sheet1!$A:$D,4,0) -> 17 | G31: =VLOOKUP(A:A,[1]Sheet1!$A:$C,3,0) -> 1 | H31: =F31-G31 -> 16 | I31: =G31/F31 -> 0.058823529 | K31: =F31*12/100 -> 2.04 | M31: =K31-L31 -> 2.04 | N31: =L31/F31 -> 0 | P31: 0 | R31: 0 | S31: 0 | T31: 0.058823529 | U31: 0 | W31: =VLOOKUP(A:A,'[1]2w & 3w'!$A:$D,4,0) -> 13 | X31: =VLOOKUP(A:A,'[1]2w & 3w'!$A:$C,3,0) -> 1 | Y31: =W31-X31 -> 12 | Z31: =X31/W31 -> 0.076923077 | AB31: =VLOOKUP(A:A,'[1]2w & 3w'!$A:$G,7,0) -> 4 | AC31: =VLOOKUP(A:A,'[1]2w & 3w'!$A:$F,6,0) -> 0 | AD31: =AB31-AC31 -> 4 | AE31: =AC31/AB31 -> 0
A32: Karimnagar | C32: 2 | F32: =VLOOKUP(A:A,[1]Sheet1!$A:$D,4,0) -> 179 | G32: =VLOOKUP(A:A,[1]Sheet1!$A:$C,3,0) -> 19 | H32: =F32-G32 -> 160 | I32: =G32/F32 -> 0.10614525 | K32: =F32*12/100 -> 21.48 | M32: =K32-L32 -> 21.48 | N32: =L32/F32 -> 0 | P32: 0.13333333 | R32: 0.05027933 | S32: 0.027932961 | T32: 0.027932961 | U32: 0 | W32: =VLOOKUP(A:A,'[1]2w & 3w'!$A:$D,4,0) -> 47 | X32: =VLOOKUP(A:A,'[1]2w & 3w'!$A:$C,3,0) -> 1 | Y32: =W32-X32 -> 46 | Z32: =X32/W32 -> 0.021276596 | AB32: =VLOOKUP(A:A,'[1]2w & 3w'!$A:$G,7,0) -> 132 | AC32: =VLOOKUP(A:A,'[1]2w & 3w'!$A:$F,6,0) -> 18 | AD32: =AB32-AC32 -> 114 | AE32: =AC32/AB32 -> 0.13636364
A33: Warangal | C33: 1 | F33: =VLOOKUP(A:A,[1]Sheet1!$A:$D,4,0) -> 142 | G33: =VLOOKUP(A:A,[1]Sheet1!$A:$C,3,0) -> 14 | H33: =F33-G33 -> 128 | I33: =G33/F33 -> 0.098591549 | K33: =F33*12/100 -> 17.04 | M33: =K33-L33 -> 17.04 | N33: =L33/F33 -> 0 | P33: 0.15853659 | R33: 0.049295775 | S33: 0.014084507 | T33: 0.021126761 | U33: 0.014084507 | W33: =VLOOKUP(A:A,'[1]2w & 3w'!$A:$D,4,0) -> 44 | X33: =VLOOKUP(A:A,'[1]2w & 3w'!$A:$C,3,0) -> 2 | Y33: =W33-X33 -> 42 | Z33: =X33/W33 -> 0.045454545 | AB33: =VLOOKUP(A:A,'[1]2w & 3w'!$A:$G,7,0) -> 98 | AC33: =VLOOKUP(A:A,'[1]2w & 3w'!$A:$F,6,0) -> 12 | AD33: =AB33-AC33 -> 86 | AE33: =AC33/AB33 -> 0.12244898
A34: NARENDER | C34: =C35+C39+C44+C50+C54+C61+C66 -> 32 | F34: =F35+F39+F44+F50+F54+F61+F66 -> 3471 | G34: =G35+G39+G44+G50+G54+G61+G66 -> 502 | H34: =H35+H39+H44+H50+H54+H61+H66 -> 2969 | I34: =G34/F34 -> 0.14462691 | K34: =K35+K39+K44+K50+K54+K61+K66 -> 416.52 | L34: =L35+L39+L44+L50+L54+L61+L66 -> 0 | M34: =M35+M39+M44+M50+M54+M61+M66 -> 416.52 | N34: =L34/F34 -> 0 | P34: 0.15698925 | R34: 0.067703832 | S34: 0.026217228 | T34: 0.018150389 | U34: 0.03255546 | W34: =W35+W39+W44+W50+W54+W61+W66 -> 1632 | X34: =X35+X39+X44+X50+X54+X61+X66 -> 176 | Y34: =Y35+Y39+Y44+Y50+Y54+Y61+Y66 -> 1456 | Z34: =X34/W34 -> 0.10784314 | AB34: =AB35+AB39+AB44+AB50+AB54+AB61+AB66 -> 1839 | AC34: =AC35+AC39+AC44+AC50+AC54+AC61+AC66 -> 326 | AD34: =AD35+AD39+AD44+AD50+AD54+AD61+AD66 -> 1513 | AE34: =AC34/AB34 -> 0.17727026
A35: Ashok | C35: =SUM(C36:C38) -> 4 | F35: =SUM(F36:F38) -> 563 | G35: =SUM(G36:G38) -> 62 | H35: =SUM(H36:H38) -> 501 | I35: =G35/F35 -> 0.11012433 | K35: =SUM(K36:K38) -> 67.56 | L35: =SUM(L36:L38) -> 0 | M35: =SUM(M36:M38) -> 67.56 | N35: =L35/F35 -> 0 | P35: 0.14681892 | R35: 0.053285968 | S35: 0.024866785 | T35: 0.01598579 | U35: 0.01598579 | W35: =SUM(W36:W38) -> 462 | X35: =SUM(X36:X38) -> 51 | Y35: =SUM(Y36:Y38) -> 411 | Z35: =X35/W35 -> 0.11038961 | AB35: =SUM(AB36:AB38) -> 101 | AC35: =SUM(AC36:AC38) -> 11 | AD35: =SUM(AD36:AD38) -> 90 | AE35: =AC35/AB35 -> 0.10891089
A36: Banswada | C36: 2 | F36: =VLOOKUP(A:A,[1]Sheet1!$A:$D,4,0) -> 201 | G36: =VLOOKUP(A:A,[1]Sheet1!$A:$C,3,0) -> 30 | H36: =F36-G36 -> 171 | I36: =G36/F36 -> 0.14925373 | K36: =F36*12/100 -> 24.12 | M36: =K36-L36 -> 24.12 | N36: =L36/F36 -> 0 | P36: 0.1509434 | R36: 0.064676617 | S36: 0.034825871 | T36: 0.024875622 | U36: 0.024875622 | W36: =VLOOKUP(A:A,'[1]2w & 3w'!$A:$D,4,0) -> 172 | X36: =VLOOKUP(A:A,'[1]2w & 3w'!$A:$C,3,0) -> 25 | Y36: =W36-X36 -> 147 | Z36: =X36/W36 -> 0.14534884 | AB36: =VLOOKUP(A:A,'[1]2w & 3w'!$A:$G,7,0) -> 29 | AC36: =VLOOKUP(A:A,'[1]2w & 3w'!$A:$F,6,0) -> 5 | AD36: =AB36-AC36 -> 24 | AE36: =AC36/AB36 -> 0.17241379
A37: Bodhan | B37: SE ex Naveen | C37: 1 | F37: =VLOOKUP(A:A,[1]Sheet1!$A:$D,4,0) -> 118 | G37: =VLOOKUP(A:A,[1]Sheet1!$A:$C,3,0) -> 14 | H37: =F37-G37 -> 104 | I37: =G37/F37 -> 0.11864407 | K37: =F37*12/100 -> 14.16 | M37: =K37-L37 -> 14.16 | N37: =L37/F37 -> 0 | P37: 0.15384615 | R37: 0.050847458 | S37: 0.042372881 | T37: 0.0084745763 | U37: 0.016949153 | W37: =VLOOKUP(A:A,'[1]2w & 3w'!$A:$D,4,0) -> 94 | X37: =VLOOKUP(A:A,'[1]2w & 3w'!$A:$C,3,0) -> 11 | Y37: =W37-X37 -> 83 | Z37: =X37/W37 -> 0.11702128 | AB37: =VLOOKUP(A:A,'[1]2w & 3w'!$A:$G,7,0) -> 24 | AC37: =VLOOKUP(A:A,'[1]2w & 3w'!$A:$F,6,0) -> 3 | AD37: =AB37-AC37 -> 21 | AE37: =AC37/AB37 -> 0.125
A38: Nizamabad | C38: 1 | F38: =VLOOKUP(A:A,[1]Sheet1!$A:$D,4,0) -> 244 | G38: =VLOOKUP(A:A,[1]Sheet1!$A:$C,3,0) -> 18 | H38: =F38-G38 -> 226 | I38: =G38/F38 -> 0.073770492 | K38: =F38*12/100 -> 29.28 | M38: =K38-L38 -> 29.28 | N38: =L38/F38 -> 0 | P38: 0.13793103 | R38: 0.045081967 | S38: 0.0081967213 | T38: 0.012295082 | U38: 0.0081967213 | W38: =VLOOKUP(A:A,'[1]2w & 3w'!$A:$D,4,0) -> 196 | X38: =VLOOKUP(A:A,'[1]2w & 3w'!$A:$C,3,0) -> 15 | Y38: =W38-X38 -> 181 | Z38: =X38/W38 -> 0.076530612 | AB38: =VLOOKUP(A:A,'[1]2w & 3w'!$A:$G,7,0) -> 48 | AC38: =VLOOKUP(A:A,'[1]2w & 3w'!$A:$F,6,0) -> 3 | AD38: =AB38-AC38 -> 45 | AE38: =AC38/AB38 -> 0.0625
A39: Vijay - Kamareddy | C39: =SUM(C40:C43) -> 3 | F39: =SUM(F40:F43) -> 485 | G39: =SUM(G40:G43) -> 67 | H39: =SUM(H40:H43) -> 418 | I39: =G39/F39 -> 0.13814433 | K39: =SUM(K40:K43) -> 58.2 | L39: =SUM(L40:L43) -> 0 | M39: =SUM(M40:M43) -> 58.2 | N39: =L39/F39 -> 0 | P39: 0.15135135 | R39: 0.059793814 | S39: 0.026804124 | T39: 0.012371134 | U39: 0.039175258 | W39: =SUM(W40:W43) -> 280 | X39: =SUM(X40:X43) -> 39 | Y39: =SUM(Y40:Y43) -> 241 | Z39: =X39/W39 -> 0.13928571 | AB39: =SUM(AB40:AB43) -> 205 | AC39: =SUM(AC40:AC43) -> 28 | AD39: =SUM(AD40:AD43) -> 177 | AE39: =AC39/AB39 -> 0.13658537
A40: Armoor (2W) | F40: =VLOOKUP(A:A,[1]Sheet1!$A:$D,4,0) -> 6 | G40: =VLOOKUP(A:A,[1]Sheet1!$A:$C,3,0) -> 0 | H40: =F40-G40 -> 6 | I40: =G40/F40 -> 0 | K40: =F40*12/100 -> 0.72 | M40: =K40-L40 -> 0.72 | N40: =L40/F40 -> 0 | P40: 0 | R40: 0 | S40: 0 | T40: 0 | U40: 0 | W40: =VLOOKUP(A:A,'[1]2w & 3w'!$A:$D,4,0) -> 5 | X40: =VLOOKUP(A:A,'[1]2w & 3w'!$A:$C,3,0) -> 0 | Y40: =W40-X40 -> 5 | Z40: =X40/W40 -> 0 | AB40: =VLOOKUP(A:A,'[1]2w & 3w'!$A:$G,7,0) -> 1 | AC40: =VLOOKUP(A:A,'[1]2w & 3w'!$A:$F,6,0) -> 0 | AD40: =AB40-AC40 -> 1 | AE40: =AC40/AB40 -> 0
...

Sheet Seizing 
A2: Date :05.11.2025
A3: Row Labels | B3: Due List Total | C3: RCVD | D3: BLC | E3: % | G3: 1st Nov | H3: 2nd Nov | I3: 3rd Nov | J3: 4th Nov | K3: 5th Nov | M3: G Total
A4: Sai Rekha | B4: =SUM(B5:B11) -> 3242 | C4: =SUM(C5:C11) -> 403 | D4: =SUM(D5:D11) -> 2839 | E4: =C4/B4 -> 0.12430598 | G4: =SUM(G5:G11) -> 0 | H4: =SUM(H5:H11) -> 0 | I4: =SUM(I5:I11) -> 4 | J4: =SUM(J5:J11) -> 3 | K4: =SUM(K5:K11) -> 2 | M4: =SUM(M5:M11) -> 9
A5: Jamanna | B5: =VLOOKUP(A:A,Sheet1!A:F,6,0) -> 562 | C5: =VLOOKUP(A:A,Sheet1!A:G,7,0) -> 61 | D5: =B5-C5 -> 501 | E5: =C5/B5 -> 0.10854093 | M5: =I5+H5+G5+J5+K5 -> 0
A6: NO_ TL bhainsa | B6: =VLOOKUP(A:A,Sheet1!A:F,6,0) -> 235 | C6: =VLOOKUP(A:A,Sheet1!A:G,7,0) -> 35 | D6: =B6-C6 -> 200 | E6: =C6/B6 -> 0.14893617 | M6: =I6+H6+G6+J6+K6 -> 0
A7: NO TL ADILABAD | B7: =VLOOKUP(A:A,Sheet1!A:F,6,0) -> 122 | C7: =VLOOKUP(A:A,Sheet1!A:G,7,0) -> 10 | D7: =B7-C7 -> 112 | E7: =C7/B7 -> 0.081967213 | M7: =I7+H7+G7+J7+K7 -> 0
A8: Vijay - MBNR | B8: =VLOOKUP(A:A,Sheet1!A:F,6,0) -> 821 | C8: =VLOOKUP(A:A,Sheet1!A:G,7,0) -> 148 | D8: =B8-C8 -> 673 | E8: =C8/B8 -> 0.18026797 | M8: =I8+H8+G8+J8+K8 -> 0
A9: Amjed Ali | B9: =VLOOKUP(A:A,Sheet1!A:F,6,0) -> 507 | C9: =VLOOKUP(A:A,Sheet1!A:G,7,0) -> 51 | D9: =B9-C9 -> 456 | E9: =C9/B9 -> 0.10059172 | J9: 1 | K9: 1 | M9: =I9+H9+G9+J9+K9 -> 2
A10: Satish | B10: =VLOOKUP(A:A,Sheet1!A:F,6,0) -> 488 | C10: =VLOOKUP(A:A,Sheet1!A:G,7,0) -> 57 | D10: =B10-C10 -> 431 | E10: =C10/B10 -> 0.11680328 | I10: 2 | J10: 1 | K10: 1 | M10: =I10+H10+G10+J10+K10 -> 4
A11: Shamshuddin | B11: =VLOOKUP(A:A,Sheet1!A:F,6,0) -> 507 | C11: =VLOOKUP(A:A,Sheet1!A:G,7,0) -> 41 | D11: =B11-C11 -> 466 | E11: =C11/B11 -> 0.08086785 | I11: 2 | J11: 1 | M11: =I11+H11+G11+J11+K11 -> 3
A12: NARENDER | B12: =SUM(B13:B19) -> 3471 | C12: =SUM(C13:C19) -> 502 | D12: =SUM(D13:D19) -> 2969 | E12: =C12/B12 -> 0.14462691 | G12: =SUM(G13:G19) -> 2 | H12: =SUM(H13:H19) -> 1 | I12: =SUM(I13:I19) -> 7 | J12: =SUM(J13:J19) -> 6 | K12: =SUM(K13:K19) -> 7 | M12: =SUM(M13:M19) -> 23
A13: Ashok | B13: =VLOOKUP(A:A,Sheet1!A:F,6,0) -> 563 | C13: =VLOOKUP(A:A,Sheet1!A:G,7,0) -> 62 | D13: =B13-C13 -> 501 | E13: =C13/B13 -> 0.11012433 | H13: 1 | J13: 2 | K13: 2 | M13: =I13+H13+G13+J13+K13 -> 5
A14: Vijay - Kamareddy | B14: =VLOOKUP(A:A,Sheet1!A:F,6,0) -> 485 | C14: =VLOOKUP(A:A,Sheet1!A:G,7,0) -> 67 | D14: =B14-C14 -> 418 | E14: =C14/B14 -> 0.13814433 | G14: 1 | I14: 2 | J14: 2 | K14: 2 | M14: =I14+H14+G14+J14+K14 -> 7
A15: Veeranna | B15: =VLOOKUP(A:A,Sheet1!A:F,6,0) -> 656 | C15: =VLOOKUP(A:A,Sheet1!A:G,7,0) -> 116 | D15: =B15-C15 -> 540 | E15: =C15/B15 -> 0.17682927 | G15: 1 | I15: 3 | K15: 1 | M15: =I15+H15+G15+J15+K15 -> 5
A16: Gnanamuthyam | B16: =VLOOKUP(A:A,Sheet1!A:F,6,0) -> 404 | C16: =VLOOKUP(A:A,Sheet1!A:G,7,0) -> 63 | D16: =B16-C16 -> 341 | E16: =C16/B16 -> 0.15594059 | J16: 1 | M16: =I16+H16+G16+J16+K16 -> 1
A17: Anumanna | B17: =VLOOKUP(A:A,Sheet1!A:F,6,0) -> 582 | C17: =VLOOKUP(A:A,Sheet1!A:G,7,0) -> 92 | D17: =B17-C17 -> 490 | E17: =C17/B17 -> 0.1580756 | I17: 2 | K17: 1 | M17: =I17+H17+G17+J17+K17 -> 3
A18: Kulayapeera | B18: =VLOOKUP(A:A,Sheet1!A:F,6,0) -> 520 | C18: =VLOOKUP(A:A,Sheet1!A:G,7,0) -> 66 | D18: =B18-C18 -> 454 | E18: =C18/B18 -> 0.12692308 | J18: 1 | K18: 1 | M18: =I18+H18+G18+J18+K18 -> 2
A19: Hindupur_Direct | B19: =VLOOKUP(A:A,Sheet1!A:F,6,0) -> 261 | C19: =VLOOKUP(A:A,Sheet1!A:G,7,0) -> 36 | D19: =B19-C19 -> 225 | E19: =C19/B19 -> 0.13793103 | M19: =I19+H19+G19+J19+K19 -> 0
A20: Priyanka | B20: =SUM(B21:B22) -> 979 | C20: =SUM(C21:C22) -> 72 | D20: =SUM(D21:D22) -> 907 | E20: =C20/B20 -> 0.073544433 | G20: =SUM(G21:G22) -> 1 | H20: =SUM(H21:H22) -> 0 | I20: =SUM(I21:I22) -> 4 | J20: =SUM(J21:J22) -> 3 | K20: =SUM(K21:K22) -> 4 | M20: =SUM(M21:M22) -> 12
A21: Siva Prasad | B21: =VLOOKUP(A:A,Sheet1!A:F,6,0) -> 544 | C21: =VLOOKUP(A:A,Sheet1!A:G,7,0) -> 38 | D21: =B21-C21 -> 506 | E21: =C21/B21 -> 0.069852941 | G21: 1 | I21: 2 | J21: 1 | K21: 3 | M21: =I21+H21+G21+J21+K21 -> 7
A22: Dadapeer | B22: =VLOOKUP(A:A,Sheet1!A:F,6,0) -> 435 | C22: =VLOOKUP(A:A,Sheet1!A:G,7,0) -> 34 | D22: =B22-C22 -> 401 | E22: =C22/B22 -> 0.07816092 | I22: 2 | J22: 2 | K22: 1 | M22: =I22+H22+G22+J22+K22 -> 5
A23: Divya | B23: =SUM(B24:B28) -> 3331 | C23: =SUM(C24:C28) -> 404 | D23: =SUM(D24:D28) -> 2927 | E23: =C23/B23 -> 0.1212849 | G23: =SUM(G24:G28) -> 1 | H23: =SUM(H24:H28) -> 0 | I23: =SUM(I24:I28) -> 3 | J23: =SUM(J24:J28) -> 6 | K23: =SUM(K24:K28) -> 4 | M23: =SUM(M24:M28) -> 14
A24: Balraju | B24: =VLOOKUP(A:A,Sheet1!A:F,6,0) -> 698 | C24: =VLOOKUP(A:A,Sheet1!A:G,7,0) -> 83 | D24: =B24-C24 -> 615 | E24: =C24/B24 -> 0.11891117 | G24: 1 | J24: 1 | K24: 1 | M24: =I24+H24+G24+J24+K24 -> 3
A25: ILYAZ | B25: =VLOOKUP(A:A,Sheet1!A:F,6,0) -> 933 | C25: =VLOOKUP(A:A,Sheet1!A:G,7,0) -> 139 | D25: =B25-C25 -> 794 | E25: =C25/B25 -> 0.14898178 | I25: 1 | J25: 2 | K25: 1 | M25: =I25+H25+G25+J25+K25 -> 4
A26: Krishnamurthy | B26: =VLOOKUP(A:A,Sheet1!A:F,6,0) -> 661 | C26: =VLOOKUP(A:A,Sheet1!A:G,7,0) -> 79 | D26: =B26-C26 -> 582 | E26: =C26/B26 -> 0.11951589 | I26: 1 | K26: 1 | M26: =I26+H26+G26+J26+K26 -> 2
A27: NO -TL - WGL | B27: =VLOOKUP(A:A,Sheet1!A:F,6,0) -> 350 | C27: =VLOOKUP(A:A,Sheet1!A:G,7,0) -> 34 | D27: =B27-C27 -> 316 | E27: =C27/B27 -> 0.097142857 | J27: 2 | M27: =I27+H27+G27+J27+K27 -> 2
A28: Murali | B28: =VLOOKUP(A:A,Sheet1!A:F,6,0) -> 689 | C28: =VLOOKUP(A:A,Sheet1!A:G,7,0) -> 69 | D28: =B28-C28 -> 620 | E28: =C28/B28 -> 0.10014514 | I28: 1 | J28: 1 | K28: 1 | M28: =I28+H28+G28+J28+K28 -> 3
A29: NAGESHWARRAO | B29: =SUM(B30:B33) -> 3279 | C29: =SUM(C30:C33) -> 322 | D29: =SUM(D30:D33) -> 2957 | E29: =C29/B29 -> 0.098200671 | G29: =SUM(G30:G33) -> 2 | H29: =SUM(H30:H33) -> 0 | I29: =SUM(I30:I33) -> 0 | J29: =SUM(J30:J33) -> 5 | K29: =SUM(K30:K33) -> 4 | M29: =SUM(M30:M33) -> 11
A30: PRAKASH | B30: =VLOOKUP(A:A,Sheet1!A:F,6,0) -> 399 | C30: =VLOOKUP(A:A,Sheet1!A:G,7,0) -> 36 | D30: =B30-C30 -> 363 | E30: =C30/B30 -> 0.090225564 | J30: 1 | K30: 1 | M30: =I30+H30+G30+J30+K30 -> 2
A31: Raju | B31: =VLOOKUP(A:A,Sheet1!A:F,6,0) -> 967 | C31: =VLOOKUP(A:A,Sheet1!A:G,7,0) -> 106 | D31: =B31-C31 -> 861 | E31: =C31/B31 -> 0.10961737 | J31: 2 | K31: 2 | M31: =I31+H31+G31+J31+K31 -> 4
A32: Satyanarayana | B32: =VLOOKUP(A:A,Sheet1!A:F,6,0) -> 860 | C32: =VLOOKUP(A:A,Sheet1!A:G,7,0) -> 108 | D32: =B32-C32 -> 752 | E32: =C32/B32 -> 0.1255814 | J32: 2 | M32: =I32+H32+G32+J32+K32 -> 2
A33: Thrinath | B33: =VLOOKUP(A:A,Sheet1!A:F,6,0) -> 1053 | C33: =VLOOKUP(A:A,Sheet1!A:G,7,0) -> 72 | D33: =B33-C33 -> 981 | E33: =C33/B33 -> 0.068376068 | G33: 2 | J33: Leave | K33: 1 | M33: =I33+H33+G33+K33 -> 3
A34: Venkanna | B34: =SUM(B35:B36) -> 1507 | C34: =SUM(C35:C36) -> 153 | D34: =SUM(D35:D36) -> 1354 | E34: =C34/B34 -> 0.10152621 | G34: =SUM(G35:G36) -> 1 | H34: =SUM(H35:H36) -> 0 | I34: =SUM(I35:I36) -> 0 | J34: =SUM(J35:J36) -> 1 | K34: =SUM(K35:K36) -> 5 | M34: =SUM(M35:M36) -> 7
A35: Abhilash | B35: =VLOOKUP(A:A,Sheet1!A:F,6,0) -> 812 | C35: =VLOOKUP(A:A,Sheet1!A:G,7,0) -> 84 | D35: =B35-C35 -> 728 | E35: =C35/B35 -> 0.10344828 | G35: 1 | K35: 3 | M35: =I35+H35+G35+J35+K35 -> 4
A36: Iliyaz - kak | B36: =VLOOKUP(A:A,Sheet1!A:F,6,0) -> 695 | C36: =VLOOKUP(A:A,Sheet1!A:G,7,0) -> 69 | D36: =B36-C36 -> 626 | E36: =C36/B36 -> 0.099280576 | J36: 1 | K36: 2 | M36: =I36+H36+G36+J36+K36 -> 3
A37: Grand Total | B37: =B34+B29+B23+B20+B12+B4 -> 15809 | C37: =C34+C29+C23+C20+C12+C4 -> 1856 | D37: =D34+D29+D23+D20+D12+D4 -> 13953 | E37: =C37/B37 -> 0.11740148 | G37: =G34+G29+G23+G20+G12+G4 -> 7 | H37: =H34+H29+H23+H20+H12+H4 -> 1 | I37: =I34+I29+I23+I20+I12+I4 -> 18 | J37: =J34+J29+J23+J20+J12+J4 -> 24 | K37: =K34+K29+K23+K20+K12+K4 -> 26 | M37: =M34+M29+M23+M20+M12+M4 -> 76
F39: KK | G39: 2 | I39: 2 | J39: 7 | K39: 9 | M39: =I39+H39+G39+J39+K39 -> 20
F40: Agency | G40: 4 | H40: 3 | I40: 14 | J40: 7 | K40: 4 | M40: =I40+H40+G40+J40+K40 -> 32
F41: Sales | K41: 1 | M41: =I41+H41+G41+J41+K41 -> 1
F42: Total | G42: =SUM(G37:G41) -> 13 | H42: =SUM(H37:H41) -> 4 | I42: =SUM(I37:I41) -> 34 | J42: =SUM(J37:J41) -> 38 | K42: =SUM(K37:K41) -> 40 | M42: =I42+H42+G42+J42+K42 -> 129
